[2022-07-05 05:31:11,814] {taskinstance.py:1037} INFO - Dependencies all met for <TaskInstance: uk_dag_test_1.kimuksung_test scheduled__2022-07-04T02:40:00+00:00 [queued]>
[2022-07-05 05:31:11,936] {taskinstance.py:1037} INFO - Dependencies all met for <TaskInstance: uk_dag_test_1.kimuksung_test scheduled__2022-07-04T02:40:00+00:00 [queued]>
[2022-07-05 05:31:11,941] {taskinstance.py:1243} INFO - 
--------------------------------------------------------------------------------
[2022-07-05 05:31:11,941] {taskinstance.py:1244} INFO - Starting attempt 1 of 1
[2022-07-05 05:31:11,942] {taskinstance.py:1245} INFO - 
--------------------------------------------------------------------------------
[2022-07-05 05:31:12,080] {taskinstance.py:1264} INFO - Executing <Task(PythonOperator): kimuksung_test> on 2022-07-04 02:40:00+00:00
[2022-07-05 05:31:12,133] {standard_task_runner.py:52} INFO - Started process 634 to run task
[2022-07-05 05:31:12,159] {standard_task_runner.py:76} INFO - Running: ['***', 'tasks', 'run', 'uk_dag_test_1', 'kimuksung_test', 'scheduled__2022-07-04T02:40:00+00:00', '--job-id', '145', '--raw', '--subdir', 'DAGS_FOLDER/test.py', '--cfg-path', '/tmp/tmp2v5taxna', '--error-file', '/tmp/tmp4a5gar93']
[2022-07-05 05:31:12,163] {standard_task_runner.py:77} INFO - Job 145: Subtask kimuksung_test
[2022-07-05 05:31:12,653] {logging_mixin.py:109} INFO - Running <TaskInstance: uk_dag_test_1.kimuksung_test scheduled__2022-07-04T02:40:00+00:00 [running]> on host 5b96eb6af7d5
[2022-07-05 05:31:12,973] {taskinstance.py:1431} INFO - Exporting the following env vars:
AIRFLOW_CTX_DAG_OWNER=***
AIRFLOW_CTX_DAG_ID=uk_dag_test_1
AIRFLOW_CTX_TASK_ID=kimuksung_test
AIRFLOW_CTX_EXECUTION_DATE=2022-07-04T02:40:00+00:00
AIRFLOW_CTX_DAG_RUN_ID=scheduled__2022-07-04T02:40:00+00:00
[2022-07-05 05:31:12,974] {logging_mixin.py:109} INFO - test function start
[2022-07-05 05:31:12,975] {taskinstance.py:1718} ERROR - Task failed with exception
Traceback (most recent call last):
  File "/home/airflow/.local/lib/python3.7/site-packages/airflow/models/taskinstance.py", line 1334, in _run_raw_task
    self._execute_task_with_callbacks(context)
  File "/home/airflow/.local/lib/python3.7/site-packages/airflow/models/taskinstance.py", line 1460, in _execute_task_with_callbacks
    result = self._execute_task(context, self.task)
  File "/home/airflow/.local/lib/python3.7/site-packages/airflow/models/taskinstance.py", line 1516, in _execute_task
    result = execute_callable(context=context)
  File "/home/airflow/.local/lib/python3.7/site-packages/airflow/operators/python.py", line 174, in execute
    return_value = self.execute_callable()
  File "/home/airflow/.local/lib/python3.7/site-packages/airflow/operators/python.py", line 188, in execute_callable
    return self.python_callable(*self.op_args, **self.op_kwargs)
  File "/opt/airflow/dags/test.py", line 21, in test
    parameter=context["paramas"]["parameter1"]
KeyError: 'paramas'
[2022-07-05 05:31:13,063] {taskinstance.py:1282} INFO - Marking task as FAILED. dag_id=uk_dag_test_1, task_id=kimuksung_test, execution_date=20220704T024000, start_date=20220705T053111, end_date=20220705T053113
[2022-07-05 05:31:13,120] {standard_task_runner.py:92} ERROR - Failed to execute job 145 for task kimuksung_test
Traceback (most recent call last):
  File "/home/airflow/.local/lib/python3.7/site-packages/airflow/task/task_runner/standard_task_runner.py", line 85, in _start_by_fork
    args.func(args, dag=self.dag)
  File "/home/airflow/.local/lib/python3.7/site-packages/airflow/cli/cli_parser.py", line 48, in command
    return func(*args, **kwargs)
  File "/home/airflow/.local/lib/python3.7/site-packages/airflow/utils/cli.py", line 92, in wrapper
    return f(*args, **kwargs)
  File "/home/airflow/.local/lib/python3.7/site-packages/airflow/cli/commands/task_command.py", line 298, in task_run
    _run_task_by_selected_method(args, dag, ti)
  File "/home/airflow/.local/lib/python3.7/site-packages/airflow/cli/commands/task_command.py", line 107, in _run_task_by_selected_method
    _run_raw_task(args, ti)
  File "/home/airflow/.local/lib/python3.7/site-packages/airflow/cli/commands/task_command.py", line 184, in _run_raw_task
    error_file=args.error_file,
  File "/home/airflow/.local/lib/python3.7/site-packages/airflow/utils/session.py", line 70, in wrapper
    return func(*args, session=session, **kwargs)
  File "/home/airflow/.local/lib/python3.7/site-packages/airflow/models/taskinstance.py", line 1334, in _run_raw_task
    self._execute_task_with_callbacks(context)
  File "/home/airflow/.local/lib/python3.7/site-packages/airflow/models/taskinstance.py", line 1460, in _execute_task_with_callbacks
    result = self._execute_task(context, self.task)
  File "/home/airflow/.local/lib/python3.7/site-packages/airflow/models/taskinstance.py", line 1516, in _execute_task
    result = execute_callable(context=context)
  File "/home/airflow/.local/lib/python3.7/site-packages/airflow/operators/python.py", line 174, in execute
    return_value = self.execute_callable()
  File "/home/airflow/.local/lib/python3.7/site-packages/airflow/operators/python.py", line 188, in execute_callable
    return self.python_callable(*self.op_args, **self.op_kwargs)
  File "/opt/airflow/dags/test.py", line 21, in test
    parameter=context["paramas"]["parameter1"]
KeyError: 'paramas'
[2022-07-05 05:31:13,178] {local_task_job.py:154} INFO - Task exited with return code 1
[2022-07-05 05:31:13,324] {local_task_job.py:264} INFO - 0 downstream tasks scheduled from follow-on schedule check
