[2022-07-19 06:31:42,396] {taskinstance.py:1037} INFO - Dependencies all met for <TaskInstance: dag_with_postgres_operator_v01.create_postgres_table manual__2022-07-19T06:31:40.778621+00:00 [queued]>
[2022-07-19 06:31:42,412] {taskinstance.py:1037} INFO - Dependencies all met for <TaskInstance: dag_with_postgres_operator_v01.create_postgres_table manual__2022-07-19T06:31:40.778621+00:00 [queued]>
[2022-07-19 06:31:42,412] {taskinstance.py:1243} INFO - 
--------------------------------------------------------------------------------
[2022-07-19 06:31:42,412] {taskinstance.py:1244} INFO - Starting attempt 1 of 6
[2022-07-19 06:31:42,412] {taskinstance.py:1245} INFO - 
--------------------------------------------------------------------------------
[2022-07-19 06:31:42,433] {taskinstance.py:1264} INFO - Executing <Task(PostgresOperator): create_postgres_table> on 2022-07-19 06:31:40.778621+00:00
[2022-07-19 06:31:42,438] {standard_task_runner.py:52} INFO - Started process 87 to run task
[2022-07-19 06:31:42,442] {standard_task_runner.py:76} INFO - Running: ['***', 'tasks', 'run', 'dag_with_postgres_operator_v01', 'create_postgres_table', 'manual__2022-07-19T06:31:40.778621+00:00', '--job-id', '46', '--raw', '--subdir', 'DAGS_FOLDER/example_postgres.py', '--cfg-path', '/tmp/tmppjm4f6_t', '--error-file', '/tmp/tmpklz5mket']
[2022-07-19 06:31:42,442] {standard_task_runner.py:77} INFO - Job 46: Subtask create_postgres_table
[2022-07-19 06:31:42,505] {logging_mixin.py:109} INFO - Running <TaskInstance: dag_with_postgres_operator_v01.create_postgres_table manual__2022-07-19T06:31:40.778621+00:00 [running]> on host 0741836b2d3b
[2022-07-19 06:31:42,570] {taskinstance.py:1431} INFO - Exporting the following env vars:
AIRFLOW_CTX_DAG_OWNER=kimuksung2
AIRFLOW_CTX_DAG_ID=dag_with_postgres_operator_v01
AIRFLOW_CTX_TASK_ID=create_postgres_table
AIRFLOW_CTX_EXECUTION_DATE=2022-07-19T06:31:40.778621+00:00
AIRFLOW_CTX_DAG_RUN_ID=manual__2022-07-19T06:31:40.778621+00:00
[2022-07-19 06:31:42,580] {base.py:79} INFO - Using connection to: id: postgres_localhost. Host: host.docker.local, Port: 5432, Schema: test, Login: ***, Password: ***, extra: {}
[2022-07-19 06:31:52,564] {local_task_job.py:212} WARNING - State of this instance has been externally set to restarting. Terminating instance.
[2022-07-19 06:31:52,566] {process_utils.py:124} INFO - Sending Signals.SIGTERM to group 87. PIDs of all processes in the group: [87]
[2022-07-19 06:31:52,566] {process_utils.py:75} INFO - Sending the signal Signals.SIGTERM to group 87
[2022-07-19 06:32:03,868] {taskinstance.py:1413} ERROR - Received SIGTERM. Terminating subprocesses.
[2022-07-19 06:32:03,887] {taskinstance.py:1718} ERROR - Task failed with exception
Traceback (most recent call last):
  File "/home/airflow/.local/lib/python3.7/site-packages/airflow/models/taskinstance.py", line 1460, in _execute_task_with_callbacks
    result = self._execute_task(context, self.task)
  File "/home/airflow/.local/lib/python3.7/site-packages/airflow/models/taskinstance.py", line 1516, in _execute_task
    result = execute_callable(context=context)
  File "/home/airflow/.local/lib/python3.7/site-packages/airflow/providers/postgres/operators/postgres.py", line 71, in execute
    self.hook.run(self.sql, self.autocommit, parameters=self.parameters)
  File "/home/airflow/.local/lib/python3.7/site-packages/airflow/hooks/dbapi.py", line 198, in run
    with closing(self.get_conn()) as conn:
  File "/home/airflow/.local/lib/python3.7/site-packages/airflow/providers/postgres/hooks/postgres.py", line 113, in get_conn
    self.conn = psycopg2.connect(**conn_args)
  File "/home/airflow/.local/lib/python3.7/site-packages/psycopg2/__init__.py", line 122, in connect
    conn = _connect(dsn, connection_factory=connection_factory, **kwasync)
psycopg2.OperationalError: connection to server at "host.docker.local" (218.38.137.27), port 5432 failed: Connection refused
	Is the server running on that host and accepting TCP/IP connections?


During handling of the above exception, another exception occurred:

Traceback (most recent call last):
  File "/home/airflow/.local/lib/python3.7/site-packages/airflow/models/taskinstance.py", line 1334, in _run_raw_task
    self._execute_task_with_callbacks(context)
  File "/home/airflow/.local/lib/python3.7/site-packages/airflow/models/taskinstance.py", line 1460, in _execute_task_with_callbacks
    result = self._execute_task(context, self.task)
  File "/home/airflow/.local/lib/python3.7/site-packages/airflow/models/taskinstance.py", line 1415, in signal_handler
    raise AirflowException("Task received SIGTERM signal")
airflow.exceptions.AirflowException: Task received SIGTERM signal
[2022-07-19 06:32:03,900] {taskinstance.py:1282} INFO - Marking task as UP_FOR_RETRY. dag_id=dag_with_postgres_operator_v01, task_id=create_postgres_table, execution_date=20220719T063140, start_date=20220719T063142, end_date=20220719T063203
[2022-07-19 06:32:03,927] {standard_task_runner.py:92} ERROR - Failed to execute job 46 for task create_postgres_table
Traceback (most recent call last):
  File "/home/airflow/.local/lib/python3.7/site-packages/airflow/models/taskinstance.py", line 1460, in _execute_task_with_callbacks
    result = self._execute_task(context, self.task)
  File "/home/airflow/.local/lib/python3.7/site-packages/airflow/models/taskinstance.py", line 1516, in _execute_task
    result = execute_callable(context=context)
  File "/home/airflow/.local/lib/python3.7/site-packages/airflow/providers/postgres/operators/postgres.py", line 71, in execute
    self.hook.run(self.sql, self.autocommit, parameters=self.parameters)
  File "/home/airflow/.local/lib/python3.7/site-packages/airflow/hooks/dbapi.py", line 198, in run
    with closing(self.get_conn()) as conn:
  File "/home/airflow/.local/lib/python3.7/site-packages/airflow/providers/postgres/hooks/postgres.py", line 113, in get_conn
    self.conn = psycopg2.connect(**conn_args)
  File "/home/airflow/.local/lib/python3.7/site-packages/psycopg2/__init__.py", line 122, in connect
    conn = _connect(dsn, connection_factory=connection_factory, **kwasync)
psycopg2.OperationalError: connection to server at "host.docker.local" (218.38.137.27), port 5432 failed: Connection refused
	Is the server running on that host and accepting TCP/IP connections?


During handling of the above exception, another exception occurred:

Traceback (most recent call last):
  File "/home/airflow/.local/lib/python3.7/site-packages/airflow/task/task_runner/standard_task_runner.py", line 85, in _start_by_fork
    args.func(args, dag=self.dag)
  File "/home/airflow/.local/lib/python3.7/site-packages/airflow/cli/cli_parser.py", line 48, in command
    return func(*args, **kwargs)
  File "/home/airflow/.local/lib/python3.7/site-packages/airflow/utils/cli.py", line 92, in wrapper
    return f(*args, **kwargs)
  File "/home/airflow/.local/lib/python3.7/site-packages/airflow/cli/commands/task_command.py", line 298, in task_run
    _run_task_by_selected_method(args, dag, ti)
  File "/home/airflow/.local/lib/python3.7/site-packages/airflow/cli/commands/task_command.py", line 107, in _run_task_by_selected_method
    _run_raw_task(args, ti)
  File "/home/airflow/.local/lib/python3.7/site-packages/airflow/cli/commands/task_command.py", line 184, in _run_raw_task
    error_file=args.error_file,
  File "/home/airflow/.local/lib/python3.7/site-packages/airflow/utils/session.py", line 70, in wrapper
    return func(*args, session=session, **kwargs)
  File "/home/airflow/.local/lib/python3.7/site-packages/airflow/models/taskinstance.py", line 1334, in _run_raw_task
    self._execute_task_with_callbacks(context)
  File "/home/airflow/.local/lib/python3.7/site-packages/airflow/models/taskinstance.py", line 1460, in _execute_task_with_callbacks
    result = self._execute_task(context, self.task)
  File "/home/airflow/.local/lib/python3.7/site-packages/airflow/models/taskinstance.py", line 1415, in signal_handler
    raise AirflowException("Task received SIGTERM signal")
airflow.exceptions.AirflowException: Task received SIGTERM signal
[2022-07-19 06:32:03,950] {process_utils.py:70} INFO - Process psutil.Process(pid=87, status='terminated', exitcode=1, started='06:31:41') (87) terminated with exit code 1
